Workbook

Sheet Income Statement
A1: 3-Statement Model — Income Statement ($mm)
A2: Line Item | B2: FY2020 | C2: FY2021 | D2: FY2022 | E2: FY2023 | F2: FY2024 | G2: FY2025
A4: Revenue
A5: Cost of Goods Sold
A6: Gross Profit | B6: =B4-B5 | C6: =C4-C5 | D6: =D4-D5 | E6: =E4-E5 | F6: =F4-F5 | G6: =G4-G5
A7: Gross Margin % | B7: =IFERROR(B6/B4,0) | C7: =IFERROR(C6/C4,0) | D7: =IFERROR(D6/D4,0) | E7: =IFERROR(E6/E4,0) | F7: =IFERROR(F6/F4,0) | G7: =IFERROR(G6/G4,0)
A9: Selling, General & Administrative
A10: Research & Development
A11: Other Operating Expenses
A12: Total Operating Expenses | B12: =B9+B10+B11 | C12: =C9+C10+C11 | D12: =D9+D10+D11 | E12: =E9+E10+E11 | F12: =F9+F10+F11 | G12: =G9+G10+G11
A14: EBITDA | B14: =B6-B12 | C14: =C6-C12 | D14: =D6-D12 | E14: =E6-E12 | F14: =F6-F12 | G14: =G6-G12
A15: EBITDA Margin % | B15: =IFERROR(B14/B4,0) | C15: =IFERROR(C14/C4,0) | D15: =IFERROR(D14/D4,0) | E15: =IFERROR(E14/E4,0) | F15: =IFERROR(F14/F4,0) | G15: =IFERROR(G14/G4,0)
A17: Depreciation & Amortization
A18: EBIT | B18: =B14-B17 | C18: =C14-C17 | D18: =D14-D17 | E18: =E14-E17 | F18: =F14-F17 | G18: =G14-G17
A19: EBIT Margin % | B19: =IFERROR(B18/B4,0) | C19: =IFERROR(C18/C4,0) | D19: =IFERROR(D18/D4,0) | E19: =IFERROR(E18/E4,0) | F19: =IFERROR(F18/F4,0) | G19: =IFERROR(G18/G4,0)
A21: Interest Income
A22: Interest Expense
A23: Net Interest Expense | B23: =B22-B21 | C23: =C22-C21 | D23: =D22-D21 | E23: =E22-E21 | F23: =F22-F21 | G23: =G22-G21
A25: Earnings Before Tax | B25: =B18-B23 | C25: =C18-C23 | D25: =D18-D23 | E25: =E18-E23 | F25: =F18-F23 | G25: =G18-G23
A26: Effective Tax Rate
A27: Income Tax Expense | B27: =MAX(B25*B26,0) | C27: =MAX(C25*C26,0) | D27: =MAX(D25*D26,0) | E27: =MAX(E25*E26,0) | F27: =MAX(F25*F26,0) | G27: =MAX(G25*G26,0)
A29: Net Income | B29: =B25-B27 | C29: =C25-C27 | D29: =D25-D27 | E29: =E25-E27 | F29: =F25-F27 | G29: =G25-G27
A30: Net Margin % | B30: =IFERROR(B29/B4,0) | C30: =IFERROR(C29/C4,0) | D30: =IFERROR(D29/D4,0) | E30: =IFERROR(E29/E4,0) | F30: =IFERROR(F29/F4,0) | G30: =IFERROR(G29/G4,0)
A32: Diluted EPS ($) | B32: =IFERROR(B29/B33,0) | C32: =IFERROR(C29/C33,0) | D32: =IFERROR(D29/D33,0) | E32: =IFERROR(E29/E33,0) | F32: =IFERROR(F29/F33,0) | G32: =IFERROR(G29/G33,0)
A33: Diluted Shares Outstanding (mm)

Sheet Balance Sheet
A1: 3-Statement Model — Balance Sheet ($mm)
A2: Line Item | B2: FY2020 | C2: FY2021 | D2: FY2022 | E2: FY2023 | F2: FY2024 | G2: FY2025
A4: ASSETS
A5: Cash & Cash Equivalents | B5: ='Cash Flow'!B36 | C5: ='Cash Flow'!C36 | D5: ='Cash Flow'!D36 | E5: ='Cash Flow'!E36 | F5: ='Cash Flow'!F36 | G5: ='Cash Flow'!G36
A6: Accounts Receivable, Net
A7: Inventory
A8: Prepaid Expenses
A9: Other Current Assets
A10: Total Current Assets | B10: =SUM(B5:B9) | C10: =SUM(C5:C9) | D10: =SUM(D5:D9) | E10: =SUM(E5:E9) | F10: =SUM(F5:F9) | G10: =SUM(G5:G9)
A12: PP&E, Gross
A13: Less: Accumulated Depreciation
A14: PP&E, Net | B14: =B12-B13 | C14: =C12-C13 | D14: =D12-D13 | E14: =E12-E13 | F14: =F12-F13 | G14: =G12-G13
A15: Goodwill
A16: Intangible Assets, Net
A17: Deferred Tax Assets
A18: Other Long-Term Assets
A19: Total Non-Current Assets | B19: =B14+B15+B16+B17+B18 | C19: =C14+C15+C16+C17+C18 | D19: =D14+D15+D16+D17+D18 | E19: =E14+E15+E16+E17+E18 | F19: =F14+F15+F16+F17+F18 | G19: =G14+G15+G16+G17+G18
A21: TOTAL ASSETS | B21: =B10+B19 | C21: =C10+C19 | D21: =D10+D19 | E21: =E10+E19 | F21: =F10+F19 | G21: =G10+G19
A23: LIABILITIES
A24: Accounts Payable
A25: Accrued Liabilities & Compensation
A26: Deferred Revenue
A27: Short-Term Debt & Commercial Paper
A28: Current Portion of Long-Term Debt
A29: Total Current Liabilities | B29: =SUM(B24:B28) | C29: =SUM(C24:C28) | D29: =SUM(D24:D28) | E29: =SUM(E24:E28) | F29: =SUM(F24:F28) | G29: =SUM(G24:G28)
A31: Long-Term Debt, Net of Current
A32: Deferred Tax Liabilities
A33: Other Long-Term Liabilities
A34: Total Non-Current Liabilities | B34: =B31+B32+B33 | C34: =C31+C32+C33 | D34: =D31+D32+D33 | E34: =E31+E32+E33 | F34: =F31+F32+F33 | G34: =G31+G32+G33
A36: TOTAL LIABILITIES | B36: =B29+B34 | C36: =C29+C34 | D36: =D29+D34 | E36: =E29+E34 | F36: =F29+F34 | G36: =G29+G34
A38: SHAREHOLDERS' EQUITY
A39: Common Stock & Additional Paid-In Capital
A40: Retained Earnings / (Accumulated Deficit) | C40: =B40+'Income Statement'!C29 | D40: =C40+'Income Statement'!D29 | E40: =D40+'Income Statement'!E29 | F40: =E40+'Income Statement'!F29 | G40: =F40+'Income Statement'!G29
A41: Treasury Stock (at cost)
A42: Accumulated OCI (Loss)
A43: Total Shareholders' Equity | B43: =B39+B40-B41+B42 | C43: =C39+C40-C41+C42 | D43: =D39+D40-D41+D42 | E43: =E39+E40-E41+E42 | F43: =F39+F40-F41+F42 | G43: =G39+G40-G41+G42
A45: TOTAL LIABILITIES + EQUITY | B45: =B36+B43 | C45: =C36+C43 | D45: =D36+D43 | E45: =E36+E43 | F45: =F36+F43 | G45: =G36+G43
A46: Balance Check (= 0 if balanced) | B46: =B21-B45 | C46: =C21-C45 | D46: =D21-D45 | E46: =E21-E45 | F46: =F21-F45 | G46: =G21-G45
A48: WORKING CAPITAL SCHEDULE
A49: Accounts Receivable | B49: =B6 | C49: =C6 | D49: =D6 | E49: =E6 | F49: =F6 | G49: =G6
...

Sheet Cash Flow
A1: 3-Statement Model — Cash Flow Statement ($mm, Indirect Method)
A2: Line Item | B2: FY2020 | C2: FY2021 | D2: FY2022 | E2: FY2023 | F2: FY2024 | G2: FY2025
A4: OPERATING ACTIVITIES
A5: Net Income | B5: ='Income Statement'!B29 | C5: ='Income Statement'!C29 | D5: ='Income Statement'!D29 | E5: ='Income Statement'!E29 | F5: ='Income Statement'!F29 | G5: ='Income Statement'!G29
A6: Add: Depreciation & Amortization | B6: ='Income Statement'!B17 | C6: ='Income Statement'!C17 | D6: ='Income Statement'!D17 | E6: ='Income Statement'!E17 | F6: ='Income Statement'!F17 | G6: ='Income Statement'!G17
A8: Changes in Working Capital
A9: (Inc.) / Dec. in Accounts Receivable | B9: =0 | C9: ='Balance Sheet'!B6-'Balance Sheet'!C6 | D9: ='Balance Sheet'!C6-'Balance Sheet'!D6 | E9: ='Balance Sheet'!D6-'Balance Sheet'!E6 | F9: ='Balance Sheet'!E6-'Balance Sheet'!F6 | G9: ='Balance Sheet'!F6-'Balance Sheet'!G6
A10: (Inc.) / Dec. in Inventory | B10: =0 | C10: ='Balance Sheet'!B7-'Balance Sheet'!C7 | D10: ='Balance Sheet'!C7-'Balance Sheet'!D7 | E10: ='Balance Sheet'!D7-'Balance Sheet'!E7 | F10: ='Balance Sheet'!E7-'Balance Sheet'!F7 | G10: ='Balance Sheet'!F7-'Balance Sheet'!G7
A11: Inc. / (Dec.) in Accounts Payable | B11: =0 | C11: ='Balance Sheet'!C24-'Balance Sheet'!B24 | D11: ='Balance Sheet'!D24-'Balance Sheet'!C24 | E11: ='Balance Sheet'!E24-'Balance Sheet'!D24 | F11: ='Balance Sheet'!F24-'Balance Sheet'!E24 | G11: ='Balance Sheet'!G24-'Balance Sheet'!F24
A12: Inc. / (Dec.) in Accrued Liabilities | B12: =0 | C12: ='Balance Sheet'!C25-'Balance Sheet'!B25 | D12: ='Balance Sheet'!D25-'Balance Sheet'!C25 | E12: ='Balance Sheet'!E25-'Balance Sheet'!D25 | F12: ='Balance Sheet'!F25-'Balance Sheet'!E25 | G12: ='Balance Sheet'!G25-'Balance Sheet'!F25
A13: Inc. / (Dec.) in Deferred Revenue | B13: =0 | C13: ='Balance Sheet'!C26-'Balance Sheet'!B26 | D13: ='Balance Sheet'!D26-'Balance Sheet'!C26 | E13: ='Balance Sheet'!E26-'Balance Sheet'!D26 | F13: ='Balance Sheet'!F26-'Balance Sheet'!E26 | G13: ='Balance Sheet'!G26-'Balance Sheet'!F26
A14: Change in Other Current Assets / Liabilities
A15: Net Change in Working Capital | B15: =SUM(B9:B14) | C15: =SUM(C9:C14) | D15: =SUM(D9:D14) | E15: =SUM(E9:E14) | F15: =SUM(F9:F14) | G15: =SUM(G9:G14)
A17: Net Cash from Operating Activities | B17: =B5+B6+B15 | C17: =C5+C6+C15 | D17: =D5+D6+D15 | E17: =E5+E6+E15 | F17: =F5+F6+F15 | G17: =G5+G6+G15
A19: INVESTING ACTIVITIES
A20: Capital Expenditures (Capex)
A21: Acquisitions, Net of Cash
A22: Proceeds from Sale of PP&E
A23: Other Investing Activities
A24: Net Cash from Investing Activities | B24: =B20+B21+B22+B23 | C24: =C20+C21+C22+C23 | D24: =D20+D21+D22+D23 | E24: =E20+E21+E22+E23 | F24: =F20+F21+F22+F23 | G24: =G20+G21+G22+G23
A26: FINANCING ACTIVITIES
A27: Proceeds from Long-Term Debt Issuance
A28: Repayment of Long-Term Debt
A29: Net Change in Short-Term Borrowings
A30: Cash Dividends Paid
A31: Share Repurchases (Buybacks)
A32: Net Cash from Financing Activities | B32: =B27+B28+B29+B30+B31 | C32: =C27+C28+C29+C30+C31 | D32: =D27+D28+D29+D30+D31 | E32: =E27+E28+E29+E30+E31 | F32: =F27+F28+F29+F30+F31 | G32: =G27+G28+G29+G30+G31
A34: Net Increase / (Decrease) in Cash | B34: =B17+B24+B32 | C34: =C17+C24+C32 | D34: =D17+D24+D32 | E34: =E17+E24+E32 | F34: =F17+F24+F32 | G34: =G17+G24+G32
A35: Cash — Beginning of Period | C35: ='Cash Flow'!B36 | D35: ='Cash Flow'!C36 | E35: ='Cash Flow'!D36 | F35: ='Cash Flow'!E36 | G35: ='Cash Flow'!F36
A36: Cash — End of Period | B36: =B35+B34 | C36: =C35+C34 | D36: =D35+D34 | E36: =E35+E34 | F36: =F35+F34 | G36: =G35+G34
